<?xml version="1.0" ?>
<robot name="Assembly" xmlns:xacro="http://www.ros.org/wiki/xacro">

<xacro:include filename="$(find Assembly_description)/urdf/materials.xacro" />
<xacro:include filename="$(find Assembly_description)/urdf/Assembly.trans" />
<xacro:include filename="$(find Assembly_description)/urdf/Assembly.gazebo" />
<link name="base_link">
  <inertial>
    <origin xyz="-0.02572645957604468 6.569516383123642e-06 0.017821626738037458" rpy="0 0 0"/>
    <mass value="4.156457046473223"/>
    <inertia ixx="0.013034" iyy="0.084094" izz="0.095033" ixy="-6e-06" iyz="0.0" ixz="0.000867"/>
  </inertial>
  <visual>
    <origin xyz="0 0 0" rpy="0 0 0"/>
    <geometry>
      <mesh filename="package://Assembly_description/meshes/base_link.stl" scale="0.001 0.001 0.001"/>
    </geometry>
    <material name="silver"/>
  </visual>
  <collision>
    <origin xyz="0 0 0" rpy="0 0 0"/>
    <geometry>
      <mesh filename="package://Assembly_description/meshes/base_link.stl" scale="0.001 0.001 0.001"/>
    </geometry>
  </collision>
</link>

<link name="rotator_left_1">
  <inertial>
    <origin xyz="4.4846516666918745e-07 0.003934914786975843 0.018000014002886432" rpy="0 0 0"/>
    <mass value="0.09154101472024741"/>
    <inertia ixx="1.1e-05" iyy="7e-06" izz="1e-05" ixy="0.0" iyz="0.0" ixz="0.0"/>
  </inertial>
  <visual>
    <origin xyz="-0.194799 -0.123074 -0.008" rpy="0 0 0"/>
    <geometry>
      <mesh filename="package://Assembly_description/meshes/rotator_left_1.stl" scale="0.001 0.001 0.001"/>
    </geometry>
    <material name="silver"/>
  </visual>
  <collision>
    <origin xyz="-0.194799 -0.123074 -0.008" rpy="0 0 0"/>
    <geometry>
      <mesh filename="package://Assembly_description/meshes/rotator_left_1.stl" scale="0.001 0.001 0.001"/>
    </geometry>
  </collision>
</link>

<link name="rotator_right_1">
  <inertial>
    <origin xyz="4.4867377607671344e-07 -0.0039356889065224054 0.018000014002296498" rpy="0 0 0"/>
    <mass value="0.0915410147202475"/>
    <inertia ixx="1.1e-05" iyy="7e-06" izz="1e-05" ixy="-0.0" iyz="-0.0" ixz="0.0"/>
  </inertial>
  <visual>
    <origin xyz="-0.194799 0.122975 -0.008" rpy="0 0 0"/>
    <geometry>
      <mesh filename="package://Assembly_description/meshes/rotator_right_1.stl" scale="0.001 0.001 0.001"/>
    </geometry>
    <material name="silver"/>
  </visual>
  <collision>
    <origin xyz="-0.194799 0.122975 -0.008" rpy="0 0 0"/>
    <geometry>
      <mesh filename="package://Assembly_description/meshes/rotator_right_1.stl" scale="0.001 0.001 0.001"/>
    </geometry>
  </collision>
</link>

<link name="wheel_back_left_1">
  <inertial>
    <origin xyz="-5.9590334083869934e-08 -0.004873834232398622 -1.6533018565301205e-09" rpy="0 0 0"/>
    <mass value="1.8001224559704576"/>
    <inertia ixx="0.001935" iyy="0.003387" izz="0.001935" ixy="0.0" iyz="-0.0" ixz="0.0"/>
  </inertial>
  <visual>
    <origin xyz="0.170156 -0.1398 -0.0205" rpy="0 0 0"/>
    <geometry>
      <mesh filename="package://Assembly_description/meshes/wheel_back_left_1.stl" scale="0.001 0.001 0.001"/>
    </geometry>
    <material name="silver"/>
  </visual>
  <collision>
    <origin xyz="0.170156 -0.1398 -0.0205" rpy="0 0 0"/>
    <geometry>
      <mesh filename="package://Assembly_description/meshes/wheel_back_left_1.stl" scale="0.001 0.001 0.001"/>
    </geometry>
  </collision>
</link>

<link name="wheel_back_right_1">
  <inertial>
    <origin xyz="-5.938171759867217e-08 0.004873835811921301 1.7874123604821879e-09" rpy="0 0 0"/>
    <mass value="1.8001224559704576"/>
    <inertia ixx="0.001935" iyy="0.003387" izz="0.001935" ixy="-0.0" iyz="-0.0" ixz="-0.0"/>
  </inertial>
  <visual>
    <origin xyz="0.170156 0.1398 -0.0205" rpy="0 0 0"/>
    <geometry>
      <mesh filename="package://Assembly_description/meshes/wheel_back_right_1.stl" scale="0.001 0.001 0.001"/>
    </geometry>
    <material name="silver"/>
  </visual>
  <collision>
    <origin xyz="0.170156 0.1398 -0.0205" rpy="0 0 0"/>
    <geometry>
      <mesh filename="package://Assembly_description/meshes/wheel_back_right_1.stl" scale="0.001 0.001 0.001"/>
    </geometry>
  </collision>
</link>

<link name="wheel_front_left_1">
  <inertial>
    <origin xyz="4.07839516408659e-07 -0.004874166721957063 -1.6533018461217797e-09" rpy="0 0 0"/>
    <mass value="1.8001224559704576"/>
    <inertia ixx="0.001935" iyy="0.003387" izz="0.001935" ixy="0.0" iyz="-0.0" ixz="0.0"/>
  </inertial>
  <visual>
    <origin xyz="-0.194799 -0.144374 -0.026" rpy="0 0 0"/>
    <geometry>
      <mesh filename="package://Assembly_description/meshes/wheel_front_left_1.stl" scale="0.001 0.001 0.001"/>
    </geometry>
    <material name="silver"/>
  </visual>
  <collision>
    <origin xyz="-0.194799 -0.144374 -0.026" rpy="0 0 0"/>
    <geometry>
      <mesh filename="package://Assembly_description/meshes/wheel_front_left_1.stl" scale="0.001 0.001 0.001"/>
    </geometry>
  </collision>
</link>

<link name="wheel_front_right_1">
  <inertial>
    <origin xyz="4.08048126010474e-07 0.0048733926024102925 1.7874124749739373e-09" rpy="0 0 0"/>
    <mass value="1.8001224559704576"/>
    <inertia ixx="0.001935" iyy="0.003387" izz="0.001935" ixy="-0.0" iyz="-0.0" ixz="-0.0"/>
  </inertial>
  <visual>
    <origin xyz="-0.194799 0.144275 -0.026" rpy="0 0 0"/>
    <geometry>
      <mesh filename="package://Assembly_description/meshes/wheel_front_right_1.stl" scale="0.001 0.001 0.001"/>
    </geometry>
    <material name="silver"/>
  </visual>
  <collision>
    <origin xyz="-0.194799 0.144275 -0.026" rpy="0 0 0"/>
    <geometry>
      <mesh filename="package://Assembly_description/meshes/wheel_front_right_1.stl" scale="0.001 0.001 0.001"/>
    </geometry>
  </collision>
</link>

<link name="hokuyo_1">
  <inertial>
    <origin xyz="0.24350755184543652 0.1300039563861765 0.029712797831224984" rpy="0 0 0"/>
    <mass value="0.36783477848639723"/>
    <inertia ixx="0.0002" iyy="0.000206" izz="0.000127" ixy="0.0" iyz="0.0" ixz="1e-06"/>
  </inertial>
  <visual>
    <origin xyz="0.128416 0.13 -0.038" rpy="0 0 0"/>
    <geometry>
      <mesh filename="package://Assembly_description/meshes/hokuyo_1.stl" scale="0.001 0.001 0.001"/>
    </geometry>
    <material name="silver"/>
  </visual>
  <collision>
    <origin xyz="0.128416 0.13 -0.038" rpy="0 0 0"/>
    <geometry>
      <mesh filename="package://Assembly_description/meshes/hokuyo_1.stl" scale="0.001 0.001 0.001"/>
    </geometry>
  </collision>
</link>

<joint name="left_wheel_rotator" type="continuous">
  <origin xyz="0.194799 0.123074 0.008" rpy="0 0 0"/>
  <parent link="base_link"/>
  <child link="rotator_left_1"/>
  <axis xyz="0.0 -0.0 1.0"/>
</joint>

<joint name="right_wheel_rotator" type="continuous">
  <origin xyz="0.194799 -0.122975 0.008" rpy="0 0 0"/>
  <parent link="base_link"/>
  <child link="rotator_right_1"/>
  <axis xyz="-0.0 -0.0 -1.0"/>
</joint>

<joint name="left_wheel_back" type="continuous">
  <origin xyz="-0.170156 0.1398 0.0205" rpy="0 0 0"/>
  <parent link="base_link"/>
  <child link="wheel_back_left_1"/>
  <axis xyz="0.0 1.0 0.0"/>
</joint>

<joint name="right_wheel_back" type="continuous">
  <origin xyz="-0.170156 -0.1398 0.0205" rpy="0 0 0"/>
  <parent link="base_link"/>
  <child link="wheel_back_right_1"/>
  <axis xyz="-0.0 -1.0 0.0"/>
</joint>

<joint name="left_wheel_front" type="continuous">
  <origin xyz="0.0 0.0213 0.018" rpy="0 0 0"/>
  <parent link="rotator_left_1"/>
  <child link="wheel_front_left_1"/>
  <axis xyz="0.0 1.0 0.0"/>
</joint>

<joint name="right_wheel_front" type="continuous">
  <origin xyz="0.0 -0.0213 0.018" rpy="0 0 0"/>
  <parent link="rotator_right_1"/>
  <child link="wheel_front_right_1"/>
  <axis xyz="-0.0 -1.0 -0.0"/>
</joint>

<joint name="Rigid 51" type="fixed">
  <origin xyz="-0.128416 -0.13 0.038" rpy="0 0 0"/>
  <parent link="base_link"/>
  <child link="hokuyo_1"/>
</joint>

</robot>
